[2025-10-23 10:15:45] - DEBUG - asyncio - Using proactor: IocpProactor
[2025-10-23 10:16:35] - ERROR - asyncio - Unclosed client session
client_session: <aiohttp.client.ClientSession object at 0x000001F1A9A55D00>
[2025-10-23 10:17:10] - DEBUG - asyncio - Using proactor: IocpProactor
[2025-10-23 10:17:25] - ERROR - asyncio - Unclosed client session
client_session: <aiohttp.client.ClientSession object at 0x0000026BD0BEAB40>
[2025-10-23 10:18:28] - DEBUG - asyncio - Using proactor: IocpProactor
[2025-10-23 10:18:40] - ERROR - asyncio - Unclosed client session
client_session: <aiohttp.client.ClientSession object at 0x000001B1507FA840>
[2025-10-23 10:20:14] - DEBUG - asyncio - Using proactor: IocpProactor
[2025-10-23 10:20:38] - ERROR - asyncio - Unclosed client session
client_session: <aiohttp.client.ClientSession object at 0x0000013FBE724A40>
[2025-10-23 10:21:45] - DEBUG - asyncio - Using proactor: IocpProactor
[2025-10-23 10:22:05] - ERROR - asyncio - Unclosed client session
client_session: <aiohttp.client.ClientSession object at 0x000001D603F72DB0>
[2025-10-23 10:28:12] - DEBUG - asyncio - Using proactor: IocpProactor
[2025-10-23 10:28:17] - ERROR - asyncio - Unclosed client session
client_session: <aiohttp.client.ClientSession object at 0x00000159A1474FE0>
[2025-10-23 10:28:18] - DEBUG - asyncio - Using proactor: IocpProactor
[2025-10-23 10:28:58] - ERROR - asyncio - Unclosed client session
client_session: <aiohttp.client.ClientSession object at 0x0000029746ACC740>
[2025-10-23 10:37:21] - DEBUG - asyncio - Using proactor: IocpProactor
[2025-10-23 10:37:21] - ERROR - TeleBot - Aiohttp ClientError: ClientConnectorDNSError
[2025-10-23 10:37:21] - ERROR - TeleBot - Infinity polling exception: Request timeout. Request: method=get url=getMe params=<aiohttp.formdata.FormData object at 0x000001F4B0304FE0> files=None request_timeout=300
[2025-10-23 10:37:21] - ERROR - TeleBot - Exception traceback:
Traceback (most recent call last):
  File "C:\Users\Stas\Documents\Python\Projects\conspectsDB\venv\Lib\site-packages\telebot\async_telebot.py", line 375, in infinity_polling
    await self._process_polling(non_stop=True, timeout=timeout, request_timeout=request_timeout,
  File "C:\Users\Stas\Documents\Python\Projects\conspectsDB\venv\Lib\site-packages\telebot\async_telebot.py", line 441, in _process_polling
    self._user = await self.get_me()
                 ^^^^^^^^^^^^^^^^^^^
  File "C:\Users\Stas\Documents\Python\Projects\conspectsDB\venv\Lib\site-packages\telebot\async_telebot.py", line 2680, in get_me
    result = await asyncio_helper.get_me(self.token)
             ^^^^^^^^^^^^^^^^^^^^^^^^^^^^^^^^^^^^^^^
  File "C:\Users\Stas\Documents\Python\Projects\conspectsDB\venv\Lib\site-packages\telebot\asyncio_helper.py", line 156, in get_me
    return await _process_request(token, method_url)
           ^^^^^^^^^^^^^^^^^^^^^^^^^^^^^^^^^^^^^^^^^
  File "C:\Users\Stas\Documents\Python\Projects\conspectsDB\venv\Lib\site-packages\telebot\asyncio_helper.py", line 105, in _process_request
    raise RequestTimeout("Request timeout. Request: method={0} url={1} params={2} files={3} request_timeout={4}".format(method, url, params, files, request_timeout, current_try))
telebot.asyncio_helper.RequestTimeout: Request timeout. Request: method=get url=getMe params=<aiohttp.formdata.FormData object at 0x000001F4B0304FE0> files=None request_timeout=300

[2025-10-23 10:37:24] - ERROR - TeleBot - Aiohttp ClientError: ClientConnectorDNSError
[2025-10-23 10:37:24] - ERROR - TeleBot - Infinity polling exception: Request timeout. Request: method=get url=getMe params=<aiohttp.formdata.FormData object at 0x000001F4B02C2FC0> files=None request_timeout=300
[2025-10-23 10:37:24] - ERROR - TeleBot - Exception traceback:
Traceback (most recent call last):
  File "C:\Users\Stas\Documents\Python\Projects\conspectsDB\venv\Lib\site-packages\telebot\async_telebot.py", line 375, in infinity_polling
    await self._process_polling(non_stop=True, timeout=timeout, request_timeout=request_timeout,
  File "C:\Users\Stas\Documents\Python\Projects\conspectsDB\venv\Lib\site-packages\telebot\async_telebot.py", line 441, in _process_polling
    self._user = await self.get_me()
                 ^^^^^^^^^^^^^^^^^^^
  File "C:\Users\Stas\Documents\Python\Projects\conspectsDB\venv\Lib\site-packages\telebot\async_telebot.py", line 2680, in get_me
    result = await asyncio_helper.get_me(self.token)
             ^^^^^^^^^^^^^^^^^^^^^^^^^^^^^^^^^^^^^^^
  File "C:\Users\Stas\Documents\Python\Projects\conspectsDB\venv\Lib\site-packages\telebot\asyncio_helper.py", line 156, in get_me
    return await _process_request(token, method_url)
           ^^^^^^^^^^^^^^^^^^^^^^^^^^^^^^^^^^^^^^^^^
  File "C:\Users\Stas\Documents\Python\Projects\conspectsDB\venv\Lib\site-packages\telebot\asyncio_helper.py", line 105, in _process_request
    raise RequestTimeout("Request timeout. Request: method={0} url={1} params={2} files={3} request_timeout={4}".format(method, url, params, files, request_timeout, current_try))
telebot.asyncio_helper.RequestTimeout: Request timeout. Request: method=get url=getMe params=<aiohttp.formdata.FormData object at 0x000001F4B02C2FC0> files=None request_timeout=300

[2025-10-23 10:37:27] - ERROR - TeleBot - Aiohttp ClientError: ClientConnectorDNSError
[2025-10-23 10:37:27] - ERROR - TeleBot - Infinity polling exception: Request timeout. Request: method=get url=getMe params=<aiohttp.formdata.FormData object at 0x000001F4B08B9610> files=None request_timeout=300
[2025-10-23 10:37:27] - ERROR - TeleBot - Exception traceback:
Traceback (most recent call last):
  File "C:\Users\Stas\Documents\Python\Projects\conspectsDB\venv\Lib\site-packages\telebot\async_telebot.py", line 375, in infinity_polling
    await self._process_polling(non_stop=True, timeout=timeout, request_timeout=request_timeout,
  File "C:\Users\Stas\Documents\Python\Projects\conspectsDB\venv\Lib\site-packages\telebot\async_telebot.py", line 441, in _process_polling
    self._user = await self.get_me()
                 ^^^^^^^^^^^^^^^^^^^
  File "C:\Users\Stas\Documents\Python\Projects\conspectsDB\venv\Lib\site-packages\telebot\async_telebot.py", line 2680, in get_me
    result = await asyncio_helper.get_me(self.token)
             ^^^^^^^^^^^^^^^^^^^^^^^^^^^^^^^^^^^^^^^
  File "C:\Users\Stas\Documents\Python\Projects\conspectsDB\venv\Lib\site-packages\telebot\asyncio_helper.py", line 156, in get_me
    return await _process_request(token, method_url)
           ^^^^^^^^^^^^^^^^^^^^^^^^^^^^^^^^^^^^^^^^^
  File "C:\Users\Stas\Documents\Python\Projects\conspectsDB\venv\Lib\site-packages\telebot\asyncio_helper.py", line 105, in _process_request
    raise RequestTimeout("Request timeout. Request: method={0} url={1} params={2} files={3} request_timeout={4}".format(method, url, params, files, request_timeout, current_try))
telebot.asyncio_helper.RequestTimeout: Request timeout. Request: method=get url=getMe params=<aiohttp.formdata.FormData object at 0x000001F4B08B9610> files=None request_timeout=300

[2025-10-23 10:37:29] - ERROR - asyncio - Unclosed client session
client_session: <aiohttp.client.ClientSession object at 0x000001F4B0474EF0>
[2025-10-23 10:37:45] - DEBUG - asyncio - Using proactor: IocpProactor
[2025-10-23 10:38:05] - ERROR - asyncio - Unclosed client session
client_session: <aiohttp.client.ClientSession object at 0x000002474ED95DC0>
[2025-10-23 10:41:05] - DEBUG - asyncio - Using proactor: IocpProactor
[2025-10-23 10:41:16] - ERROR - asyncio - Unclosed client session
client_session: <aiohttp.client.ClientSession object at 0x000001E0DDA84740>
[2025-10-23 10:42:15] - DEBUG - asyncio - Using proactor: IocpProactor
[2025-10-23 10:42:45] - ERROR - asyncio - Unclosed client session
client_session: <aiohttp.client.ClientSession object at 0x000001C587B597C0>
[2025-10-23 10:43:17] - DEBUG - asyncio - Using proactor: IocpProactor
[2025-10-23 10:43:55] - ERROR - asyncio - Unclosed client session
client_session: <aiohttp.client.ClientSession object at 0x000002138F67C080>
[2025-10-23 10:44:59] - DEBUG - asyncio - Using proactor: IocpProactor
[2025-10-23 10:44:59] - INFO - code.logging - Запуск polling...
[2025-10-23 10:45:59] - ERROR - TeleBot - Aiohttp ClientError: ClientConnectorError
[2025-10-23 10:45:59] - ERROR - TeleBot - Infinity polling exception: Request timeout. Request: method=get url=getMe params=<aiohttp.formdata.FormData object at 0x00000258101E28A0> files=None request_timeout=300
[2025-10-23 10:45:59] - ERROR - TeleBot - Exception traceback:
Traceback (most recent call last):
  File "C:\Users\Stas\Documents\Python\Projects\conspectsDB\venv\Lib\site-packages\telebot\async_telebot.py", line 375, in infinity_polling
    await self._process_polling(non_stop=True, timeout=timeout, request_timeout=request_timeout,
  File "C:\Users\Stas\Documents\Python\Projects\conspectsDB\venv\Lib\site-packages\telebot\async_telebot.py", line 441, in _process_polling
    self._user = await self.get_me()
                 ^^^^^^^^^^^^^^^^^^^
  File "C:\Users\Stas\Documents\Python\Projects\conspectsDB\venv\Lib\site-packages\telebot\async_telebot.py", line 2680, in get_me
    result = await asyncio_helper.get_me(self.token)
             ^^^^^^^^^^^^^^^^^^^^^^^^^^^^^^^^^^^^^^^
  File "C:\Users\Stas\Documents\Python\Projects\conspectsDB\venv\Lib\site-packages\telebot\asyncio_helper.py", line 156, in get_me
    return await _process_request(token, method_url)
           ^^^^^^^^^^^^^^^^^^^^^^^^^^^^^^^^^^^^^^^^^
  File "C:\Users\Stas\Documents\Python\Projects\conspectsDB\venv\Lib\site-packages\telebot\asyncio_helper.py", line 105, in _process_request
    raise RequestTimeout("Request timeout. Request: method={0} url={1} params={2} files={3} request_timeout={4}".format(method, url, params, files, request_timeout, current_try))
telebot.asyncio_helper.RequestTimeout: Request timeout. Request: method=get url=getMe params=<aiohttp.formdata.FormData object at 0x00000258101E28A0> files=None request_timeout=300

[2025-10-23 10:46:06] - INFO - code.logging - Прервано пользователем (KeyboardInterrupt)
[2025-10-23 10:46:06] - ERROR - asyncio - Unclosed client session
client_session: <aiohttp.client.ClientSession object at 0x0000025810653260>
[2025-10-23 10:46:08] - DEBUG - asyncio - Using proactor: IocpProactor
[2025-10-23 10:46:08] - INFO - code.logging - Starting polling...
[2025-10-23 10:46:09] - INFO - code.logging - Interrupted by user (KeyboardInterrupt)
[2025-10-23 10:46:09] - ERROR - asyncio - Unclosed client session
client_session: <aiohttp.client.ClientSession object at 0x00000210B4CEF0E0>
[2025-10-23 10:46:12] - DEBUG - asyncio - Using proactor: IocpProactor
[2025-10-23 10:46:12] - INFO - code.logging - Starting polling...
[2025-10-23 10:46:53] - INFO - code.logging - Interrupted by user (KeyboardInterrupt)
[2025-10-23 10:46:53] - ERROR - asyncio - Unclosed client session
client_session: <aiohttp.client.ClientSession object at 0x000001C9720A7C80>
[2025-10-23 10:46:55] - DEBUG - asyncio - Using proactor: IocpProactor
[2025-10-23 10:46:55] - INFO - code.logging - Starting polling...
[2025-10-23 10:47:55] - ERROR - TeleBot - Aiohttp ClientError: ClientConnectorError
[2025-10-23 10:47:55] - ERROR - TeleBot - Infinity polling exception: Request timeout. Request: method=get url=getMe params=<aiohttp.formdata.FormData object at 0x00000226DD275D00> files=None request_timeout=300
[2025-10-23 10:47:55] - ERROR - TeleBot - Exception traceback:
Traceback (most recent call last):
  File "C:\Users\Stas\Documents\Python\Projects\conspectsDB\venv\Lib\site-packages\telebot\async_telebot.py", line 375, in infinity_polling
    await self._process_polling(non_stop=True, timeout=timeout, request_timeout=request_timeout,
  File "C:\Users\Stas\Documents\Python\Projects\conspectsDB\venv\Lib\site-packages\telebot\async_telebot.py", line 441, in _process_polling
    self._user = await self.get_me()
                 ^^^^^^^^^^^^^^^^^^^
  File "C:\Users\Stas\Documents\Python\Projects\conspectsDB\venv\Lib\site-packages\telebot\async_telebot.py", line 2680, in get_me
    result = await asyncio_helper.get_me(self.token)
             ^^^^^^^^^^^^^^^^^^^^^^^^^^^^^^^^^^^^^^^
  File "C:\Users\Stas\Documents\Python\Projects\conspectsDB\venv\Lib\site-packages\telebot\asyncio_helper.py", line 156, in get_me
    return await _process_request(token, method_url)
           ^^^^^^^^^^^^^^^^^^^^^^^^^^^^^^^^^^^^^^^^^
  File "C:\Users\Stas\Documents\Python\Projects\conspectsDB\venv\Lib\site-packages\telebot\asyncio_helper.py", line 105, in _process_request
    raise RequestTimeout("Request timeout. Request: method={0} url={1} params={2} files={3} request_timeout={4}".format(method, url, params, files, request_timeout, current_try))
telebot.asyncio_helper.RequestTimeout: Request timeout. Request: method=get url=getMe params=<aiohttp.formdata.FormData object at 0x00000226DD275D00> files=None request_timeout=300

[2025-10-23 10:48:05] - INFO - code.logging - Interrupted by user (KeyboardInterrupt)
[2025-10-23 10:48:05] - ERROR - asyncio - Unclosed client session
client_session: <aiohttp.client.ClientSession object at 0x00000226DD983170>
[2025-10-23 10:48:27] - DEBUG - asyncio - Using proactor: IocpProactor
[2025-10-23 10:48:27] - INFO - code.logging - Starting polling...
[2025-10-23 10:49:27] - ERROR - TeleBot - Aiohttp ClientError: ClientConnectorError
[2025-10-23 10:49:27] - ERROR - TeleBot - Infinity polling exception: Request timeout. Request: method=get url=getMe params=<aiohttp.formdata.FormData object at 0x0000023F9C115D00> files=None request_timeout=300
[2025-10-23 10:49:27] - ERROR - TeleBot - Exception traceback:
Traceback (most recent call last):
  File "C:\Users\Stas\Documents\Python\Projects\conspectsDB\venv\Lib\site-packages\telebot\async_telebot.py", line 375, in infinity_polling
    await self._process_polling(non_stop=True, timeout=timeout, request_timeout=request_timeout,
  File "C:\Users\Stas\Documents\Python\Projects\conspectsDB\venv\Lib\site-packages\telebot\async_telebot.py", line 441, in _process_polling
    self._user = await self.get_me()
                 ^^^^^^^^^^^^^^^^^^^
  File "C:\Users\Stas\Documents\Python\Projects\conspectsDB\venv\Lib\site-packages\telebot\async_telebot.py", line 2680, in get_me
    result = await asyncio_helper.get_me(self.token)
             ^^^^^^^^^^^^^^^^^^^^^^^^^^^^^^^^^^^^^^^
  File "C:\Users\Stas\Documents\Python\Projects\conspectsDB\venv\Lib\site-packages\telebot\asyncio_helper.py", line 156, in get_me
    return await _process_request(token, method_url)
           ^^^^^^^^^^^^^^^^^^^^^^^^^^^^^^^^^^^^^^^^^
  File "C:\Users\Stas\Documents\Python\Projects\conspectsDB\venv\Lib\site-packages\telebot\asyncio_helper.py", line 105, in _process_request
    raise RequestTimeout("Request timeout. Request: method={0} url={1} params={2} files={3} request_timeout={4}".format(method, url, params, files, request_timeout, current_try))
telebot.asyncio_helper.RequestTimeout: Request timeout. Request: method=get url=getMe params=<aiohttp.formdata.FormData object at 0x0000023F9C115D00> files=None request_timeout=300

[2025-10-23 10:50:30] - ERROR - TeleBot - Aiohttp ClientError: ClientConnectorError
[2025-10-23 10:50:30] - ERROR - TeleBot - Infinity polling exception: Request timeout. Request: method=get url=getMe params=<aiohttp.formdata.FormData object at 0x0000023F9C5005C0> files=None request_timeout=300
[2025-10-23 10:50:30] - ERROR - TeleBot - Exception traceback:
Traceback (most recent call last):
  File "C:\Users\Stas\Documents\Python\Projects\conspectsDB\venv\Lib\site-packages\telebot\async_telebot.py", line 375, in infinity_polling
    await self._process_polling(non_stop=True, timeout=timeout, request_timeout=request_timeout,
  File "C:\Users\Stas\Documents\Python\Projects\conspectsDB\venv\Lib\site-packages\telebot\async_telebot.py", line 441, in _process_polling
    self._user = await self.get_me()
                 ^^^^^^^^^^^^^^^^^^^
  File "C:\Users\Stas\Documents\Python\Projects\conspectsDB\venv\Lib\site-packages\telebot\async_telebot.py", line 2680, in get_me
    result = await asyncio_helper.get_me(self.token)
             ^^^^^^^^^^^^^^^^^^^^^^^^^^^^^^^^^^^^^^^
  File "C:\Users\Stas\Documents\Python\Projects\conspectsDB\venv\Lib\site-packages\telebot\asyncio_helper.py", line 156, in get_me
    return await _process_request(token, method_url)
           ^^^^^^^^^^^^^^^^^^^^^^^^^^^^^^^^^^^^^^^^^
  File "C:\Users\Stas\Documents\Python\Projects\conspectsDB\venv\Lib\site-packages\telebot\asyncio_helper.py", line 105, in _process_request
    raise RequestTimeout("Request timeout. Request: method={0} url={1} params={2} files={3} request_timeout={4}".format(method, url, params, files, request_timeout, current_try))
telebot.asyncio_helper.RequestTimeout: Request timeout. Request: method=get url=getMe params=<aiohttp.formdata.FormData object at 0x0000023F9C5005C0> files=None request_timeout=300

[2025-10-23 10:50:43] - INFO - code.logging - Interrupted by user (KeyboardInterrupt)
[2025-10-23 10:50:43] - ERROR - asyncio - Unclosed client session
client_session: <aiohttp.client.ClientSession object at 0x0000023F9C8B33E0>
[2025-10-23 10:50:45] - DEBUG - asyncio - Using selector: SelectSelector
[2025-10-23 10:50:45] - INFO - code.logging - Starting polling...
[2025-10-23 10:51:42] - DEBUG - asyncio - Using selector: SelectSelector
[2025-10-23 10:51:42] - INFO - code.logging - Starting polling...
[2025-10-23 10:51:46] - DEBUG - code.logging - /start command
[2025-10-23 10:51:46] - INFO - code.logging - Connecting to database...
[2025-10-23 10:51:46] - INFO - code.logging - Successfully connected to database.
[2025-10-23 10:51:46] - INFO - code.logging - Check if "USERS" entry exists with filters={'telegram_id': '848623786'}...
[2025-10-23 10:51:46] - DEBUG - code.logging - SQL: SELECT 1 FROM USERS WHERE telegram_id = ? LIMIT 1 -- params=('848623786',)
[2025-10-23 10:51:46] - INFO - code.logging - No matching rows found
[2025-10-23 10:51:46] - DEBUG - code.logging - /start command
[2025-10-23 10:51:46] - INFO - code.logging - Connecting to database...
[2025-10-23 10:51:46] - INFO - code.logging - Successfully connected to database.
[2025-10-23 10:51:46] - INFO - code.logging - Check if "USERS" entry exists with filters={'telegram_id': '848623786'}...
[2025-10-23 10:51:46] - DEBUG - code.logging - SQL: SELECT 1 FROM USERS WHERE telegram_id = ? LIMIT 1 -- params=('848623786',)
[2025-10-23 10:51:46] - INFO - code.logging - No matching rows found
[2025-10-23 10:51:46] - DEBUG - code.logging - /start command
[2025-10-23 10:51:46] - INFO - code.logging - Connecting to database...
[2025-10-23 10:51:46] - INFO - code.logging - Successfully connected to database.
[2025-10-23 10:51:46] - INFO - code.logging - Check if "USERS" entry exists with filters={'telegram_id': '848623786'}...
[2025-10-23 10:51:46] - DEBUG - code.logging - SQL: SELECT 1 FROM USERS WHERE telegram_id = ? LIMIT 1 -- params=('848623786',)
[2025-10-23 10:51:46] - INFO - code.logging - No matching rows found
[2025-10-23 10:51:46] - DEBUG - code.logging - /start command
[2025-10-23 10:51:46] - INFO - code.logging - Connecting to database...
[2025-10-23 10:51:46] - INFO - code.logging - Successfully connected to database.
[2025-10-23 10:51:46] - INFO - code.logging - Check if "USERS" entry exists with filters={'telegram_id': '848623786'}...
[2025-10-23 10:51:46] - DEBUG - code.logging - SQL: SELECT 1 FROM USERS WHERE telegram_id = ? LIMIT 1 -- params=('848623786',)
[2025-10-23 10:51:46] - INFO - code.logging - No matching rows found
[2025-10-23 10:51:46] - DEBUG - code.logging - /start command
[2025-10-23 10:51:46] - INFO - code.logging - Connecting to database...
[2025-10-23 10:51:46] - INFO - code.logging - Successfully connected to database.
[2025-10-23 10:51:46] - INFO - code.logging - Check if "USERS" entry exists with filters={'telegram_id': '848623786'}...
[2025-10-23 10:51:46] - DEBUG - code.logging - SQL: SELECT 1 FROM USERS WHERE telegram_id = ? LIMIT 1 -- params=('848623786',)
[2025-10-23 10:51:46] - INFO - code.logging - No matching rows found
[2025-10-23 10:51:46] - DEBUG - code.logging - /start command
[2025-10-23 10:51:46] - INFO - code.logging - Connecting to database...
[2025-10-23 10:51:46] - INFO - code.logging - Successfully connected to database.
[2025-10-23 10:51:46] - INFO - code.logging - Check if "USERS" entry exists with filters={'telegram_id': '848623786'}...
[2025-10-23 10:51:46] - DEBUG - code.logging - SQL: SELECT 1 FROM USERS WHERE telegram_id = ? LIMIT 1 -- params=('848623786',)
[2025-10-23 10:51:46] - INFO - code.logging - No matching rows found
[2025-10-23 10:51:46] - DEBUG - code.logging - /start command
[2025-10-23 10:51:46] - INFO - code.logging - Connecting to database...
[2025-10-23 10:51:46] - INFO - code.logging - Successfully connected to database.
[2025-10-23 10:51:46] - INFO - code.logging - Check if "USERS" entry exists with filters={'telegram_id': '848623786'}...
[2025-10-23 10:51:46] - DEBUG - code.logging - SQL: SELECT 1 FROM USERS WHERE telegram_id = ? LIMIT 1 -- params=('848623786',)
[2025-10-23 10:51:46] - INFO - code.logging - No matching rows found
[2025-10-23 10:51:46] - DEBUG - code.logging - /start command
[2025-10-23 10:51:46] - INFO - code.logging - Connecting to database...
[2025-10-23 10:51:46] - INFO - code.logging - Successfully connected to database.
[2025-10-23 10:51:46] - INFO - code.logging - Check if "USERS" entry exists with filters={'telegram_id': '848623786'}...
[2025-10-23 10:51:46] - DEBUG - code.logging - SQL: SELECT 1 FROM USERS WHERE telegram_id = ? LIMIT 1 -- params=('848623786',)
[2025-10-23 10:51:46] - INFO - code.logging - No matching rows found
[2025-10-23 10:51:46] - DEBUG - code.logging - /start command
[2025-10-23 10:51:46] - INFO - code.logging - Connecting to database...
[2025-10-23 10:51:46] - INFO - code.logging - Successfully connected to database.
[2025-10-23 10:51:46] - INFO - code.logging - Check if "USERS" entry exists with filters={'telegram_id': '848623786'}...
[2025-10-23 10:51:46] - DEBUG - code.logging - SQL: SELECT 1 FROM USERS WHERE telegram_id = ? LIMIT 1 -- params=('848623786',)
[2025-10-23 10:51:46] - INFO - code.logging - No matching rows found
[2025-10-23 10:51:46] - DEBUG - code.logging - /start command
[2025-10-23 10:51:46] - INFO - code.logging - Connecting to database...
[2025-10-23 10:51:46] - INFO - code.logging - Successfully connected to database.
[2025-10-23 10:51:46] - INFO - code.logging - Check if "USERS" entry exists with filters={'telegram_id': '848623786'}...
[2025-10-23 10:51:46] - DEBUG - code.logging - SQL: SELECT 1 FROM USERS WHERE telegram_id = ? LIMIT 1 -- params=('848623786',)
[2025-10-23 10:51:46] - INFO - code.logging - No matching rows found
[2025-10-23 10:51:46] - DEBUG - code.logging - /start command
[2025-10-23 10:51:46] - INFO - code.logging - Connecting to database...
[2025-10-23 10:51:46] - INFO - code.logging - Successfully connected to database.
[2025-10-23 10:51:46] - INFO - code.logging - Check if "USERS" entry exists with filters={'telegram_id': '848623786'}...
[2025-10-23 10:51:46] - DEBUG - code.logging - SQL: SELECT 1 FROM USERS WHERE telegram_id = ? LIMIT 1 -- params=('848623786',)
[2025-10-23 10:51:46] - INFO - code.logging - No matching rows found
[2025-10-23 10:51:46] - DEBUG - code.logging - /start command
[2025-10-23 10:51:46] - INFO - code.logging - Connecting to database...
[2025-10-23 10:51:46] - INFO - code.logging - Successfully connected to database.
[2025-10-23 10:51:46] - INFO - code.logging - Check if "USERS" entry exists with filters={'telegram_id': '848623786'}...
[2025-10-23 10:51:46] - DEBUG - code.logging - SQL: SELECT 1 FROM USERS WHERE telegram_id = ? LIMIT 1 -- params=('848623786',)
[2025-10-23 10:51:46] - INFO - code.logging - No matching rows found
[2025-10-23 10:51:46] - DEBUG - code.logging - /start command
[2025-10-23 10:51:46] - INFO - code.logging - Connecting to database...
[2025-10-23 10:51:46] - INFO - code.logging - Successfully connected to database.
[2025-10-23 10:51:46] - INFO - code.logging - Check if "USERS" entry exists with filters={'telegram_id': '848623786'}...
[2025-10-23 10:51:46] - DEBUG - code.logging - SQL: SELECT 1 FROM USERS WHERE telegram_id = ? LIMIT 1 -- params=('848623786',)
[2025-10-23 10:51:46] - INFO - code.logging - No matching rows found
[2025-10-23 10:51:46] - DEBUG - code.logging - /start command
[2025-10-23 10:51:46] - INFO - code.logging - Connecting to database...
[2025-10-23 10:51:46] - INFO - code.logging - Successfully connected to database.
[2025-10-23 10:51:46] - INFO - code.logging - Check if "USERS" entry exists with filters={'telegram_id': '848623786'}...
[2025-10-23 10:51:46] - DEBUG - code.logging - SQL: SELECT 1 FROM USERS WHERE telegram_id = ? LIMIT 1 -- params=('848623786',)
[2025-10-23 10:51:46] - INFO - code.logging - No matching rows found
[2025-10-23 10:51:46] - DEBUG - code.logging - /start command
[2025-10-23 10:51:46] - INFO - code.logging - Connecting to database...
[2025-10-23 10:51:46] - INFO - code.logging - Successfully connected to database.
[2025-10-23 10:51:46] - INFO - code.logging - Check if "USERS" entry exists with filters={'telegram_id': '848623786'}...
[2025-10-23 10:51:46] - DEBUG - code.logging - SQL: SELECT 1 FROM USERS WHERE telegram_id = ? LIMIT 1 -- params=('848623786',)
[2025-10-23 10:51:46] - INFO - code.logging - No matching rows found
[2025-10-23 10:51:46] - DEBUG - code.logging - /start command
[2025-10-23 10:51:46] - INFO - code.logging - Connecting to database...
[2025-10-23 10:51:46] - INFO - code.logging - Successfully connected to database.
[2025-10-23 10:51:46] - INFO - code.logging - Check if "USERS" entry exists with filters={'telegram_id': '848623786'}...
[2025-10-23 10:51:46] - DEBUG - code.logging - SQL: SELECT 1 FROM USERS WHERE telegram_id = ? LIMIT 1 -- params=('848623786',)
[2025-10-23 10:51:46] - INFO - code.logging - No matching rows found
[2025-10-23 10:51:46] - DEBUG - code.logging - /start command
[2025-10-23 10:51:46] - INFO - code.logging - Connecting to database...
[2025-10-23 10:51:46] - INFO - code.logging - Successfully connected to database.
[2025-10-23 10:51:46] - INFO - code.logging - Check if "USERS" entry exists with filters={'telegram_id': '848623786'}...
[2025-10-23 10:51:46] - DEBUG - code.logging - SQL: SELECT 1 FROM USERS WHERE telegram_id = ? LIMIT 1 -- params=('848623786',)
[2025-10-23 10:51:46] - INFO - code.logging - No matching rows found
[2025-10-23 10:51:55] - INFO - code.logging - Connecting to database...
[2025-10-23 10:51:55] - INFO - code.logging - Successfully connected to database.
[2025-10-23 10:51:55] - INFO - code.logging - Getting rows from "FACULTS" with filters=None...
[2025-10-23 10:51:55] - DEBUG - code.logging - SQL: SELECT rowid, * FROM FACULTS -- params=()
[2025-10-23 10:51:55] - INFO - code.logging - Successfully fetched rows
[2025-10-23 10:51:55] - INFO - code.logging - Trying to get column names from cursor
[2025-10-23 10:51:55] - INFO - code.logging - Successfully parsed columns names
[2025-10-23 10:51:55] - INFO - code.logging - Trying to get column names from cursor
[2025-10-23 10:51:55] - INFO - code.logging - Successfully parsed columns names
[2025-10-23 10:51:55] - INFO - code.logging - Trying to get column names from cursor
[2025-10-23 10:51:55] - INFO - code.logging - Successfully parsed columns names
[2025-10-23 10:51:55] - INFO - code.logging - Trying to get column names from cursor
[2025-10-23 10:51:55] - INFO - code.logging - Successfully parsed columns names
[2025-10-23 10:51:55] - INFO - code.logging - Trying to get column names from cursor
[2025-10-23 10:51:55] - INFO - code.logging - Successfully parsed columns names
[2025-10-23 10:51:55] - INFO - code.logging - Trying to get column names from cursor
[2025-10-23 10:51:55] - INFO - code.logging - Successfully parsed columns names
[2025-10-23 10:51:56] - INFO - code.logging - Connecting to database...
[2025-10-23 10:51:56] - INFO - code.logging - Successfully connected to database.
[2025-10-23 10:51:56] - INFO - code.logging - Getting rows from "FACULTS" with filters=None...
[2025-10-23 10:51:56] - DEBUG - code.logging - SQL: SELECT rowid, * FROM FACULTS -- params=()
[2025-10-23 10:51:56] - INFO - code.logging - Successfully fetched rows
[2025-10-23 10:51:56] - INFO - code.logging - Trying to get column names from cursor
[2025-10-23 10:51:56] - INFO - code.logging - Successfully parsed columns names
[2025-10-23 10:51:56] - INFO - code.logging - Trying to get column names from cursor
[2025-10-23 10:51:56] - INFO - code.logging - Successfully parsed columns names
[2025-10-23 10:51:56] - INFO - code.logging - Trying to get column names from cursor
[2025-10-23 10:51:56] - INFO - code.logging - Successfully parsed columns names
[2025-10-23 10:51:56] - INFO - code.logging - Trying to get column names from cursor
[2025-10-23 10:51:56] - INFO - code.logging - Successfully parsed columns names
[2025-10-23 10:51:56] - INFO - code.logging - Trying to get column names from cursor
[2025-10-23 10:51:56] - INFO - code.logging - Successfully parsed columns names
[2025-10-23 10:51:56] - INFO - code.logging - Trying to get column names from cursor
[2025-10-23 10:51:56] - INFO - code.logging - Successfully parsed columns names
[2025-10-23 10:51:58] - ERROR - TeleBot - A request to the Telegram API was unsuccessful. Error code: 400. Description: Bad Request: message is not modified: specified new message content and reply markup are exactly the same as a current content and reply markup of the message
[2025-10-23 10:52:00] - INFO - code.logging - Connecting to database...
[2025-10-23 10:52:00] - INFO - code.logging - Successfully connected to database.
[2025-10-23 10:52:00] - INFO - code.logging - Getting rows from "FACULTS" with filters=None...
[2025-10-23 10:52:00] - DEBUG - code.logging - SQL: SELECT rowid, * FROM FACULTS -- params=()
[2025-10-23 10:52:00] - INFO - code.logging - Successfully fetched rows
[2025-10-23 10:52:00] - INFO - code.logging - Trying to get column names from cursor
[2025-10-23 10:52:00] - INFO - code.logging - Successfully parsed columns names
[2025-10-23 10:52:00] - INFO - code.logging - Trying to get column names from cursor
[2025-10-23 10:52:00] - INFO - code.logging - Successfully parsed columns names
[2025-10-23 10:52:00] - INFO - code.logging - Trying to get column names from cursor
[2025-10-23 10:52:00] - INFO - code.logging - Successfully parsed columns names
[2025-10-23 10:52:00] - INFO - code.logging - Trying to get column names from cursor
[2025-10-23 10:52:00] - INFO - code.logging - Successfully parsed columns names
[2025-10-23 10:52:00] - INFO - code.logging - Trying to get column names from cursor
[2025-10-23 10:52:00] - INFO - code.logging - Successfully parsed columns names
[2025-10-23 10:52:00] - INFO - code.logging - Trying to get column names from cursor
[2025-10-23 10:52:00] - INFO - code.logging - Successfully parsed columns names
[2025-10-23 10:52:00] - ERROR - TeleBot - A request to the Telegram API was unsuccessful. Error code: 400. Description: Bad Request: message is not modified: specified new message content and reply markup are exactly the same as a current content and reply markup of the message
